ERROR:asyncio:Task exception was never retrieved
future: <Task finished name='Task-243' coro=<TsharkXmlParser.get_packets_from_stream() done, defined at C:\Users\bharg\network-forensics\Lib\site-packages\pyshark\tshark\output_parser\tshark_xml.py:24> exception=EOFError()>
Traceback (most recent call last):
  File "C:\Users\bharg\network-forensics\main.py", line 25, in <module>
    main()
  File "C:\Users\bharg\network-forensics\main.py", line 14, in main
    capture_packets(args.interface)
  File "C:\Users\bharg\network-forensics\packet_capture.py", line 7, in capture_packets
    for packet in cap:
  File "C:\Users\bharg\network-forensics\Lib\site-packages\pyshark\capture\capture.py", line 221, in _packets_from_tshark_sync
    packet, data = self.eventloop.run_until_complete(
                   ^^^^^^^^^^^^^^^^^^^^^^^^^^^^^^^^^^
  File "C:\Program Files\WindowsApps\PythonSoftwareFoundation.Python.3.11_3.11.2544.0_x64__qbz5n2kfra8p0\Lib\asyncio\base_events.py", line 641, in run_until_complete
    self.run_forever()
  File "C:\Program Files\WindowsApps\PythonSoftwareFoundation.Python.3.11_3.11.2544.0_x64__qbz5n2kfra8p0\Lib\asyncio\windows_events.py", line 321, in run_forever
    super().run_forever()
  File "C:\Program Files\WindowsApps\PythonSoftwareFoundation.Python.3.11_3.11.2544.0_x64__qbz5n2kfra8p0\Lib\asyncio\base_events.py", line 608, in run_forever
    self._run_once()
  File "C:\Program Files\WindowsApps\PythonSoftwareFoundation.Python.3.11_3.11.2544.0_x64__qbz5n2kfra8p0\Lib\asyncio\base_events.py", line 1898, in _run_once
    event_list = self._selector.select(timeout)
                 ^^^^^^^^^^^^^^^^^^^^^^^^^^^^^^
  File "C:\Program Files\WindowsApps\PythonSoftwareFoundation.Python.3.11_3.11.2544.0_x64__qbz5n2kfra8p0\Lib\asyncio\windows_events.py", line 444, in select
    self._poll(timeout)
  File "C:\Program Files\WindowsApps\PythonSoftwareFoundation.Python.3.11_3.11.2544.0_x64__qbz5n2kfra8p0\Lib\asyncio\windows_events.py", line 825, in _poll
    status = _overlapped.GetQueuedCompletionStatus(self._iocp, ms)
             ^^^^^^^^^^^^^^^^^^^^^^^^^^^^^^^^^^^^^^^^^^^^^^^^^^^^^
KeyboardInterrupt

During handling of the above exception, another exception occurred:

Traceback (most recent call last):
  File "C:\Users\bharg\network-forensics\Lib\site-packages\pyshark\tshark\output_parser\tshark_xml.py", line 27, in get_packets_from_stream
    return await super().get_packets_from_stream(stream, existing_data, got_first_packet=got_first_packet)
           ^^^^^^^^^^^^^^^^^^^^^^^^^^^^^^^^^^^^^^^^^^^^^^^^^^^^^^^^^^^^^^^^^^^^^^^^^^^^^^^^^^^^^^^^^^^^^^^
  File "C:\Users\bharg\network-forensics\Lib\site-packages\pyshark\tshark\output_parser\base_parser.py", line 22, in get_packets_from_stream
    raise EOFError()
EOFError
